Workbook

Sheet AIRCRAFT MODELS
A1: Aircraft Type | B1: Max Positions | C1: Main Deck Pos | D1: Lower Deck Pos | E1: CG Forward (m) | F1: CG Aft (m) | G1: Max Payload (kg)
A2: A320 | B2: 12 | C2: 0 | D2: 12 | E2: 14 | F2: 28 | G2: 20000
A3: B737 | B3: 4 | C3: 0 | D3: 4 | E3: 12.5 | F3: 24.5 | G3: 20000
A4: B777 | B4: 12 | C4: 6 | D4: 6 | E4: 15 | F4: 30 | G4: 100000
A5: B777F | B5: 12 | C5: 6 | D5: 6 | E5: 15 | F5: 30 | G5: 100000
A6: B747F | B6: 14 | C6: 10 | D6: 4 | E6: 16 | F6: 32 | G6: 120000

Sheet POSITION CONFIGURATIONS
A1: Position | B1: Arm (m) | C1: Deck | D1: Aircraft
A2: A1 | B2: 12.5 | C2: Lower | D2: A320
A3: A2 | B3: 13 | C3: Lower | D3: A320
A4: B1 | B4: 16 | C4: Lower | D4: A320
A5: B2 | B5: 16.5 | C5: Lower | D5: A320
A6: C1 | B6: 19.5 | C6: Lower | D6: A320
A7: C2 | B7: 20 | C7: Lower | D7: A320
A8: D1 | B8: 23 | C8: Lower | D8: A320
A9: D2 | B9: 23.5 | C9: Lower | D9: A320
A10: E1 | B10: 27 | C10: Lower | D10: A320
A11: E2 | B11: 27.5 | C11: Lower | D11: A320
A12: F1 | B12: 31 | C12: Lower | D12: A320
A13: F2 | B13: 31.5 | C13: Lower | D13: A320
... A55: L4 | B55: 25 | C55: Lower | D55: B747F

Sheet ULD LOAD INPUT
A1: Position | B1: ULD Type | C1: Weight (kg) | D1: Destination | F1: 📝 INSTRUCTIONS
A2: M1 | B2: PMC | C2: 3200 | D2: DXB | F2: 1. Edit Weight values (blue numbers)
A3: M2 | B3: PAG | C3: 4200 | D3: DXB | F3: 2. Select ULD Type from dropdown
A4: M3 | B4: PMC | C4: 5200 | D4: DXB | F4: 3. All calculations update automatically
A5: M4 | B5: PMC | C5: 5200 | D5: DXB | F5: 4. Check TRIM SHEET for results
A6: M5 | B6: PMC | C6: 4200 | D6: DXB
A7: M6 | B7: PMC | C7: 3200 | D7: DXB
A8: M7 | B8: PAG | C8: 1100 | D8: DXB
A9: M8 | B9: PMC | C9: 1400 | D9: DXB
A10: M9 | B10: PMC | C10: 1700 | D10: DXB
A11: M10 | B11: PMC | C11: 1700 | D11: DXB
A12: L1 | B12: LD-3 | C12: 1400 | D12: DXB
A13: L2 | B13: LD-3 | C13: 1100 | D13: DXB
A14: L3 | B14: LD-3 | C14: 1500 | D14: DXB

Sheet ULD MASTER TABLE
A1: ULD Type | B1: Max Weight (kg) | C1: Deck | D1: Compatible Aircraft
A2: LD-3 | B2: 1588 | C2: Lower | D2: A320,B737,B777
A3: LD-7 | B3: 4600 | C3: Main | D3: A320,B777
A4: PMC | B4: 6804 | C4: Main | D4: A320,B777
A5: PAG | B5: 6000 | C5: Main | D5: A320,B777
A6: AKE | B6: 1588 | C6: Lower | D6: B737
A7: AKH | B7: 1134 | C7: Lower | D7: B737
A8: PLA | B8: 6033 | C8: Main | D8: B777

Sheet CARGO HOLD VISUAL LAYOUT
A1: AI CARGO HOLD MONITORING - VISUAL INSPECTION SYSTEM
A3: Position | B3: ULD Type | C3: Actual Weight | D3: Max Weight | E3: Utilization % | F3: Status
A4: ='ULD LOAD INPUT'!A2 -> M1 | B4: ='ULD LOAD INPUT'!B2 -> PMC | C4: ='ULD LOAD INPUT'!C2 -> 3200 | D4: =INDEX('ULD MASTER TABLE'!$B$2:$B$5,MATCH(B4,'ULD MASTER TABLE'!$A$2:$A$5,0)) -> 6804 | E4: =IF(D4=0,0,C4/D4) -> 0.47031158 | F4: =IF(C4>D4,"OVERLOAD",IF(C4>=D4*0.9,"NEAR LIMIT","SAFE")) -> SAFE
A5: ='ULD LOAD INPUT'!A3 -> M2 | B5: ='ULD LOAD INPUT'!B3 -> PAG | C5: ='ULD LOAD INPUT'!C3 -> 4200 | D5: =INDEX('ULD MASTER TABLE'!$B$2:$B$5,MATCH(B5,'ULD MASTER TABLE'!$A$2:$A$5,0)) -> 6000 | E5: =IF(D5=0,0,C5/D5) -> 0.7 | F5: =IF(C5>D5,"OVERLOAD",IF(C5>=D5*0.9,"NEAR LIMIT","SAFE")) -> SAFE
A6: ='ULD LOAD INPUT'!A4 -> M3 | B6: ='ULD LOAD INPUT'!B4 -> PMC | C6: ='ULD LOAD INPUT'!C4 -> 5200 | D6: =INDEX('ULD MASTER TABLE'!$B$2:$B$5,MATCH(B6,'ULD MASTER TABLE'!$A$2:$A$5,0)) -> 6804 | E6: =IF(D6=0,0,C6/D6) -> 0.76425632 | F6: =IF(C6>D6,"OVERLOAD",IF(C6>=D6*0.9,"NEAR LIMIT","SAFE")) -> SAFE
A7: ='ULD LOAD INPUT'!A5 -> M4 | B7: ='ULD LOAD INPUT'!B5 -> PMC | C7: ='ULD LOAD INPUT'!C5 -> 5200 | D7: =INDEX('ULD MASTER TABLE'!$B$2:$B$5,MATCH(B7,'ULD MASTER TABLE'!$A$2:$A$5,0)) -> 6804 | E7: =IF(D7=0,0,C7/D7) -> 0.76425632 | F7: =IF(C7>D7,"OVERLOAD",IF(C7>=D7*0.9,"NEAR LIMIT","SAFE")) -> SAFE
A8: ='ULD LOAD INPUT'!A6 -> M5 | B8: ='ULD LOAD INPUT'!B6 -> PMC | C8: ='ULD LOAD INPUT'!C6 -> 4200 | D8: =INDEX('ULD MASTER TABLE'!$B$2:$B$5,MATCH(B8,'ULD MASTER TABLE'!$A$2:$A$5,0)) -> 6804 | E8: =IF(D8=0,0,C8/D8) -> 0.61728395 | F8: =IF(C8>D8,"OVERLOAD",IF(C8>=D8*0.9,"NEAR LIMIT","SAFE")) -> SAFE
A9: ='ULD LOAD INPUT'!A7 -> M6 | B9: ='ULD LOAD INPUT'!B7 -> PMC | C9: ='ULD LOAD INPUT'!C7 -> 3200 | D9: =INDEX('ULD MASTER TABLE'!$B$2:$B$5,MATCH(B9,'ULD MASTER TABLE'!$A$2:$A$5,0)) -> 6804 | E9: =IF(D9=0,0,C9/D9) -> 0.47031158 | F9: =IF(C9>D9,"OVERLOAD",IF(C9>=D9*0.9,"NEAR LIMIT","SAFE")) -> SAFE
A10: ='ULD LOAD INPUT'!A8 -> M7 | B10: ='ULD LOAD INPUT'!B8 -> PAG | C10: ='ULD LOAD INPUT'!C8 -> 1100 | D10: =INDEX('ULD MASTER TABLE'!$B$2:$B$5,MATCH(B10,'ULD MASTER TABLE'!$A$2:$A$5,0)) -> 6000 | E10: =IF(D10=0,0,C10/D10) -> 0.18333333 | F10: =IF(C10>D10,"OVERLOAD",IF(C10>=D10*0.9,"NEAR LIMIT","SAFE")) -> SAFE
A11: ='ULD LOAD INPUT'!A9 -> M8 | B11: ='ULD LOAD INPUT'!B9 -> PMC | C11: ='ULD LOAD INPUT'!C9 -> 1400 | D11: =INDEX('ULD MASTER TABLE'!$B$2:$B$5,MATCH(B11,'ULD MASTER TABLE'!$A$2:$A$5,0)) -> 6804 | E11: =IF(D11=0,0,C11/D11) -> 0.20576132 | F11: =IF(C11>D11,"OVERLOAD",IF(C11>=D11*0.9,"NEAR LIMIT","SAFE")) -> SAFE
A12: ='ULD LOAD INPUT'!A10 -> M9 | B12: ='ULD LOAD INPUT'!B10 -> PMC | C12: ='ULD LOAD INPUT'!C10 -> 1700 | D12: =INDEX('ULD MASTER TABLE'!$B$2:$B$5,MATCH(B12,'ULD MASTER TABLE'!$A$2:$A$5,0)) -> 6804 | E12: =IF(D12=0,0,C12/D12) -> 0.24985303 | F12: =IF(C12>D12,"OVERLOAD",IF(C12>=D12*0.9,"NEAR LIMIT","SAFE")) -> SAFE
A13: ='ULD LOAD INPUT'!A11 -> M10 | B13: ='ULD LOAD INPUT'!B11 -> PMC | C13: ='ULD LOAD INPUT'!C11 -> 1700 | D13: =INDEX('ULD MASTER TABLE'!$B$2:$B$5,MATCH(B13,'ULD MASTER TABLE'!$A$2:$A$5,0)) -> 6804 | E13: =IF(D13=0,0,C13/D13) -> 0.24985303 | F13: =IF(C13>D13,"OVERLOAD",IF(C13>=D13*0.9,"NEAR LIMIT","SAFE")) -> SAFE
A14: ='ULD LOAD INPUT'!A12 -> L1 | B14: ='ULD LOAD INPUT'!B12 -> LD-3 | C14: ='ULD LOAD INPUT'!C12 -> 1400 | D14: =INDEX('ULD MASTER TABLE'!$B$2:$B$5,MATCH(B14,'ULD MASTER TABLE'!$A$2:$A$5,0)) -> 1588 | E14: =IF(D14=0,0,C14/D14) -> 0.88161209 | F14: =IF(C14>D14,"OVERLOAD",IF(C14>=D14*0.9,"NEAR LIMIT","SAFE")) -> SAFE
A15: ='ULD LOAD INPUT'!A13 -> L2 | B15: ='ULD LOAD INPUT'!B13 -> LD-3 | C15: ='ULD LOAD INPUT'!C13 -> 1100 | D15: =INDEX('ULD MASTER TABLE'!$B$2:$B$5,MATCH(B15,'ULD MASTER TABLE'!$A$2:$A$5,0)) -> 1588 | E15: =IF(D15=0,0,C15/D15) -> 0.69269521 | F15: =IF(C15>D15,"OVERLOAD",IF(C15>=D15*0.9,"NEAR LIMIT","SAFE")) -> SAFE

Sheet ARM & MOMENT COMPUTATION
A1: PHYSICS CALCULATION ENGINE - CENTER OF GRAVITY ANALYSIS
A3: Position | B3: ULD Type | C3: Arm (m) | D3: Weight (kg) | E3: Moment (kg·m)
A4: ='ULD LOAD INPUT'!A2 -> M1 | B4: ='ULD LOAD INPUT'!B2 -> PMC | C4: =IFERROR( SUMPRODUCT( ('POSITION CONFIGURATIONS'!$A$2:$A$50=A4)* ('POSITION CONFIGURATIONS'!$D$2:$D$50='AIRCRAFT LOAD & TRIM SHEET'!$I$3)* 'POSITION CONFIGURATIONS'!$B$2:$B$50 ), 0 ) -> 14 | D4: ='ULD LOAD INPUT'!C2 -> 3200 | E4: =D4*C4 -> 44800
A5: ='ULD LOAD INPUT'!A3 -> M2 | B5: ='ULD LOAD INPUT'!B3 -> PAG | C5: =IFERROR( SUMPRODUCT( ('POSITION CONFIGURATIONS'!$A$2:$A$50=A5)* ('POSITION CONFIGURATIONS'!$D$2:$D$50='AIRCRAFT LOAD & TRIM SHEET'!$I$3)* 'POSITION CONFIGURATIONS'!$B$2:$B$50 ), 0 ) -> 15.5 | D5: ='ULD LOAD INPUT'!C3 -> 4200 | E5: =D5*C5 -> 65100
A6: ='ULD LOAD INPUT'!A4 -> M3 | B6: ='ULD LOAD INPUT'!B4 -> PMC | C6: =IFERROR( SUMPRODUCT( ('POSITION CONFIGURATIONS'!$A$2:$A$50=A6)* ('POSITION CONFIGURATIONS'!$D$2:$D$50='AIRCRAFT LOAD & TRIM SHEET'!$I$3)* 'POSITION CONFIGURATIONS'!$B$2:$B$50 ), 0 ) -> 17 | D6: ='ULD LOAD INPUT'!C4 -> 5200 | E6: =D6*C6 -> 88400
A7: ='ULD LOAD INPUT'!A5 -> M4 | B7: ='ULD LOAD INPUT'!B5 -> PMC | C7: =IFERROR( SUMPRODUCT( ('POSITION CONFIGURATIONS'!$A$2:$A$50=A7)* ('POSITION CONFIGURATIONS'!$D$2:$D$50='AIRCRAFT LOAD & TRIM SHEET'!$I$3)* 'POSITION CONFIGURATIONS'!$B$2:$B$50 ), 0 ) -> 18.5 | D7: ='ULD LOAD INPUT'!C5 -> 5200 | E7: =D7*C7 -> 96200
A8: ='ULD LOAD INPUT'!A6 -> M5 | B8: ='ULD LOAD INPUT'!B6 -> PMC | C8: =IFERROR( SUMPRODUCT( ('POSITION CONFIGURATIONS'!$A$2:$A$50=A8)* ('POSITION CONFIGURATIONS'!$D$2:$D$50='AIRCRAFT LOAD & TRIM SHEET'!$I$3)* 'POSITION CONFIGURATIONS'!$B$2:$B$50 ), 0 ) -> 20 | D8: ='ULD LOAD INPUT'!C6 -> 4200 | E8: =D8*C8 -> 84000
A9: ='ULD LOAD INPUT'!A7 -> M6 | B9: ='ULD LOAD INPUT'!B7 -> PMC | C9: =IFERROR( SUMPRODUCT( ('POSITION CONFIGURATIONS'!$A$2:$A$50=A9)* ('POSITION CONFIGURATIONS'!$D$2:$D$50='AIRCRAFT LOAD & TRIM SHEET'!$I$3)* 'POSITION CONFIGURATIONS'!$B$2:$B$50 ), 0 ) -> 21.5 | D9: ='ULD LOAD INPUT'!C7 -> 3200 | E9: =D9*C9 -> 68800
A10: ='ULD LOAD INPUT'!A8 -> M7 | B10: ='ULD LOAD INPUT'!B8 -> PAG | C10: =IFERROR( SUMPRODUCT( ('POSITION CONFIGURATIONS'!$A$2:$A$50=A10)* ('POSITION CONFIGURATIONS'!$D$2:$D$50='AIRCRAFT LOAD & TRIM SHEET'!$I$3)* 'POSITION CONFIGURATIONS'!$B$2:$B$50 ), 0 ) -> 23 | D10: ='ULD LOAD INPUT'!C8 -> 1100 | E10: =D10*C10 -> 25300
A11: ='ULD LOAD INPUT'!A9 -> M8 | B11: ='ULD LOAD INPUT'!B9 -> PMC | C11: =IFERROR( SUMPRODUCT( ('POSITION CONFIGURATIONS'!$A$2:$A$50=A11)* ('POSITION CONFIGURATIONS'!$D$2:$D$50='AIRCRAFT LOAD & TRIM SHEET'!$I$3)* 'POSITION CONFIGURATIONS'!$B$2:$B$50 ), 0 ) -> 24.5 | D11: ='ULD LOAD INPUT'!C9 -> 1400 | E11: =D11*C11 -> 34300
A12: ='ULD LOAD INPUT'!A10 -> M9 | B12: ='ULD LOAD INPUT'!B10 -> PMC | C12: =IFERROR( SUMPRODUCT( ('POSITION CONFIGURATIONS'!$A$2:$A$50=A12)* ('POSITION CONFIGURATIONS'!$D$2:$D$50='AIRCRAFT LOAD & TRIM SHEET'!$I$3)* 'POSITION CONFIGURATIONS'!$B$2:$B$50 ), 0 ) -> 26 | D12: ='ULD LOAD INPUT'!C10 -> 1700 | E12: =D12*C12 -> 44200
A13: ='ULD LOAD INPUT'!A11 -> M10 | B13: ='ULD LOAD INPUT'!B11 -> PMC | C13: =IFERROR( SUMPRODUCT( ('POSITION CONFIGURATIONS'!$A$2:$A$50=A13)* ('POSITION CONFIGURATIONS'!$D$2:$D$50='AIRCRAFT LOAD & TRIM SHEET'!$I$3)* 'POSITION CONFIGURATIONS'!$B$2:$B$50 ), 0 ) -> 0 | D13: ='ULD LOAD INPUT'!C11 -> 1700 | E13: =D13*C13 -> 0
A14: ='ULD LOAD INPUT'!A12 -> L1 | B14: ='ULD LOAD INPUT'!B12 -> LD-3 | C14: =IFERROR( SUMPRODUCT( ('POSITION CONFIGURATIONS'!$A$2:$A$50=A14)* ('POSITION CONFIGURATIONS'!$D$2:$D$50='AIRCRAFT LOAD & TRIM SHEET'!$I$3)* 'POSITION CONFIGURATIONS'!$B$2:$B$50 ), 0 ) -> 0 | D14: ='ULD LOAD INPUT'!C12 -> 1400 | E14: =D14*C14 -> 0
A15: ='ULD LOAD INPUT'!A13 -> L2 | B15: ='ULD LOAD INPUT'!B13 -> LD-3 | C15: =IFERROR( SUMPRODUCT( ('POSITION CONFIGURATIONS'!$A$2:$A$50=A15)* ('POSITION CONFIGURATIONS'!$D$2:$D$50='AIRCRAFT LOAD & TRIM SHEET'!$I$3)* 'POSITION CONFIGURATIONS'!$B$2:$B$50 ), 0 ) -> 0 | D15: ='ULD LOAD INPUT'!C13 -> 1100 | E15: =D15*C15 -> 0
C17: TOTALS: | D17: =SUM(D4:D16) -> 33600 | E17: =SUM(E4:E16) -> 551100

Sheet CG & BALANCE DECISION ENGINE
A1: AI SAFETY EVALUATION & DECISION SYSTEM
A3: AIRCRAFT PARAMETERS
A4: Aircraft Type: | B4: ='AIRCRAFT LOAD & TRIM SHEET'!I3 -> B747F
A6: CG SAFETY ENVELOPE
A7: Forward CG Limit (m): | B7: =INDEX('AIRCRAFT MODELS'!E:E,MATCH('AIRCRAFT LOAD & TRIM SHEET'!I3,'AIRCRAFT MODELS'!A:A,0)) -> 16
A8: Aft CG Limit (m): | B8: =INDEX('AIRCRAFT MODELS'!F:F,MATCH('AIRCRAFT LOAD & TRIM SHEET'!I3,'AIRCRAFT MODELS'!A:A,0)) -> 32
A11: COMPUTED VALUES
A12: Total Cargo Weight (kg): | B12: ='ARM & MOMENT COMPUTATION'!D17 -> 33600
A13: Total Moment (kg·m): | B13: ='ARM & MOMENT COMPUTATION'!E17 -> 551100
A15: CENTER OF GRAVITY (m): | B15: =IF(B12=0,0,B13/B12) -> 16.401786
A18: AI SAFETY DECISION
A19: CG Status: | B19: =IF(B15<B7,"⚠ FORWARD CG LIMIT EXCEEDED",IF(B15>B8,"⚠ AFT CG LIMIT EXCEEDED","✓ CG WITHIN SAFE ENVELOPE")) -> ✓ CG WITHIN SAFE ENVELOPE
A21: Overall Load Safety: | B21: =IF(COUNTIF('CARGO HOLD VISUAL LAYOUT'!F:F,"OVERLOAD")>0,"✖ NOT SAFE - OVERLOAD DETECTED",IF(OR(B15<B7,B15>B8),"✖ NOT SAFE - CG OUT OF LIMITS","✓ SAFE FOR FLIGHT")) -> ✓ SAFE FOR FLIGHT

Sheet AIRCRAFT LOAD & TRIM SHEET
A1: AIRCRAFT LOAD AND TRIM SHEET
A2: AI-POWERED LOAD PLANNING SYSTEM | AUTO-GENERATED DOCUMENT
A3: AIRCRAFT SELECTION | E3: Selected Aircraft Model | I3: B747F
A5: FLIGHT INFORMATION | I5: SYSTEM INFORMATION
A6: Aircraft Type: | B6: ='AIRCRAFT LOAD & TRIM SHEET'!I3 -> B747F | I6: Load Controller: | J6: AI SYSTEM
A7: Flight Number: | B7: CA-8042 | I7: Status: | J7: AUTO-GENERATED
A8: Route: | B8: PVG → LAX | I8: Version: | J8: v1.0
A9: Date: | B9: =TEXT(TODAY(),"DD-MMM-YYYY") -> 10-Feb-2026 | I9: Time: | J9: =TEXT(NOW(),"HH:MM") -> 03:23
A11: 🛫 AIRCRAFT CARGO HOLD - VISUAL LOAD DISTRIBUTION
A12: TOP VIEW - CARGO COMPARTMENTS
G13: ▲ NOSE
C15: POS A1 | K15: POS A2
C16: ='ULD LOAD INPUT'!B2&" "&TEXT('ULD LOAD INPUT'!C2,"#,##0")&" kg" -> PMC 3,200 kg | K16: ='ULD LOAD INPUT'!B8&" "&TEXT('ULD LOAD INPUT'!C8,"#,##0")&" kg" -> PAG 1,100 kg
C17: ='CARGO HOLD VISUAL LAYOUT'!F2 -> 0 | K17: ='CARGO HOLD VISUAL LAYOUT'!F8 -> SAFE
C18: POS B1 | K18: POS B2
C19: ='ULD LOAD INPUT'!B3&" "&TEXT('ULD LOAD INPUT'!C3,"#,##0")&" kg" -> PAG 4,200 kg | K19: ='ULD LOAD INPUT'!B9&" "&TEXT('ULD LOAD INPUT'!C9,"#,##0")&" kg" -> PMC 1,400 kg
C20: ='CARGO HOLD VISUAL LAYOUT'!F3 -> Status | K20: ='CARGO HOLD VISUAL LAYOUT'!F9 -> SAFE
C21: POS C1 | K21: POS C2
C22: ='ULD LOAD INPUT'!B4&" "&TEXT('ULD LOAD INPUT'!C4,"#,##0")&" kg" -> PMC 5,200 kg | K22: ='ULD LOAD INPUT'!B10&" "&TEXT('ULD LOAD INPUT'!C10,"#,##0")&" kg" -> PMC 1,700 kg
C23: ='CARGO HOLD VISUAL LAYOUT'!F4 -> SAFE | K23: ='CARGO HOLD VISUAL LAYOUT'!F10 -> SAFE
C24: POS D1 | K24: POS D2
C25: ='ULD LOAD INPUT'!B5&" "&TEXT('ULD LOAD INPUT'!C5,"#,##0")&" kg" -> PMC 5,200 kg | K25: ='ULD LOAD INPUT'!B11&" "&TEXT('ULD LOAD INPUT'!C11,"#,##0")&" kg" -> PMC 1,700 kg
C26: ='CARGO HOLD VISUAL LAYOUT'!F5 -> SAFE | K26: ='CARGO HOLD VISUAL LAYOUT'!F11 -> SAFE
C27: POS E1 | K27: POS E2
C28: ='ULD LOAD INPUT'!B6&" "&TEXT('ULD LOAD INPUT'!C6,"#,##0")&" kg" -> PMC 4,200 kg | K28: ='ULD LOAD INPUT'!B12&" "&TEXT('ULD LOAD INPUT'!C12,"#,##0")&" kg" -> LD-3 1,400 kg
C29: ='CARGO HOLD VISUAL LAYOUT'!F6 -> SAFE | K29: ='CARGO HOLD VISUAL LAYOUT'!F12 -> SAFE
C30: POS F1 | K30: POS F2
C31: ='ULD LOAD INPUT'!B7&" "&TEXT('ULD LOAD INPUT'!C7,"#,##0")&" kg" -> PMC 3,200 kg | K31: ='ULD LOAD INPUT'!B13&" "&TEXT('ULD LOAD INPUT'!C13,"#,##0")&" kg" -> LD-3 1,100 kg
C32: ='CARGO HOLD VISUAL LAYOUT'!F7 -> SAFE | K32: ='CARGO HOLD VISUAL LAYOUT'!F13 -> SAFE
G33: ▼ TAIL
A35: LOAD SUMMARY | I35: CENTER OF GRAVITY ANALYSIS
A36: Total Cargo Weight: | C36: ='CG & BALANCE DECISION ENGINE'!B12&" kg" -> 33600 kg | I36: Computed CG: | K36: =TEXT('CG & BALANCE DECISION ENGINE'!B15,"0.00")&" m" -> 16.40 m
A37: Total ULD Count: | C37: =COUNTA('ULD LOAD INPUT'!B2:B13) -> 12 | I37: Forward Limit: | K37: =TEXT('CG & BALANCE DECISION ENGINE'!B7,"0.00")&" m" -> 16.00 m
A38: Main Deck Weight: | C38: =SUMIF('ULD MASTER TABLE'!C:C,"Main",'ARM & MOMENT COMPUTATION'!D4:D15)&" kg" -> 16000 kg | I38: Aft Limit: | K38: =TEXT('CG & BALANCE DECISION ENGINE'!B8,"0.00")&" m" -> 32.00 m
A39: Lower Deck Weight: | C39: =SUMIF('ULD MASTER TABLE'!C:C,"Lower",'ARM & MOMENT COMPUTATION'!D4:D15)&" kg" -> 8500 kg | I39: CG Status: | K39: ='CG & BALANCE DECISION ENGINE'!B19 -> ✓ CG WITHIN SAFE ENVELOPE
A40: Overload Alerts: | C40: =COUNTIF('CARGO HOLD VISUAL LAYOUT'!F:F,"OVERLOAD") -> 0
I41: CG ENVELOPE VISUALIZATION
A42: ⚠️ FLIGHT SAFETY STATUS
I43: Forward Limit | J43: ='CG & BALANCE DECISION ENGINE'!B7 -> 16
A44: ='CG & BALANCE DECISION ENGINE'!B21 -> ✓ SAFE FOR FLIGHT | I44: Current CG | J44: ='CG & BALANCE DECISION ENGINE'!B15 -> 16.401786
...

Sheet AI SYSTEM EXPLANATION
A1: EXPLAINABLE AI SYSTEM DOCUMENTATION
A2: SECTION | B2: DESCRIPTION | C2: HOW IT WORKS
A4: 1. AI KNOWLEDGE BASE | B4: ULD MASTER TABLE sheet | C4: Stores aircraft cargo container specifications. Acts as AI 'memory' that the system queries for weight limits and deck assignments.
A6: 2. KNOWLEDGE LOOKUP | B6: XLOOKUP formulas | C6: Simulates AI information retrieval. When user enters a ULD type, formulas automatically fetch max weight from knowledge base.
A8: 3. RULE-BASED INFERENCE | B8: IF-THEN logic in formulas | C8: AI decision-making using nested IF statements: IF weight > max THEN OVERLOAD, ELSE IF weight > 90% THEN NEAR LIMIT, ELSE SAFE
A10: 4. REAL-TIME MONITORING | B10: Dynamic cell updates | C10: All calculations update instantly when user changes input. Simulates AI continuously monitoring cargo status.
A12: 5. VISUAL INSPECTION | B12: CARGO HOLD VISUAL LAYOUT | C12: Color-coded status display (Red/Yellow/Green) represents AI visual pattern recognition of unsafe conditions.
A14: 6. PHYSICS ENGINE | B14: Weight × Arm = Moment | C14: Automated calculation of aircraft balance physics. CG = Total Moment / Total Weight computed automatically.
A16: 7. SAFETY DECISION LOGIC | B16: CG & BALANCE DECISION ENGINE | C16: AI evaluates if CG is within 14-28m envelope. Makes binary safety decision: SAFE or NOT SAFE for flight.
A18: 8. AUTOMATED REPORTING | B18: AUTO-GENERATED TRIM SHEET | C18: AI compiles all data into professional flight document automatically. No manual intervention required.
A20: WHY THIS IS AI:
A21: • Knowledge Representation | C21: Structured data storage (ULD Master Table)
A22: • Inference Engine | C22: Rule-based decision making (IF-THEN logic)
A23: • Automated Reasoning | C23: CG safety evaluation without human input
A24: • Pattern Recognition | C24: Visual status monitoring and alerts
A25: • Expert System | C25: Encodes aviation engineering expertise in formulas
A27: EXPLAINABILITY:
A28: Every decision can be traced:
A29: 1. Input → Which ULD type selected
A30: 2. Lookup → What max weight retrieved
A31: 3. Comparison → Weight vs limit calculation
A32: 4. Decision → Clear status determination
A33: 5. Output → Visible in trim sheet
A35: This represents a transparent, rule-based AI system where every calculation and decision is visible and auditable.
